<?xml version="1.0" ?>
<sdf version='1.6'>
  <world name='default'>
    <light name='sun' type='directional'>
      <cast_shadows>1</cast_shadows>
      <pose frame=''>0 0 10 0 -0 0</pose>
      <diffuse>0.8 0.8 0.8 1</diffuse>
      <specular>0.2 0.2 0.2 1</specular>
      <attenuation>
        <range>1000</range>
        <constant>0.9</constant>
        <linear>0.01</linear>
        <quadratic>0.001</quadratic>
      </attenuation>
      <direction>-0.5 0.1 -0.9</direction>
    </light>
    <model name='ground_plane'>
      <static>1</static>
      <link name='link'>
        <collision name='collision'>
          <geometry>
            <plane>
              <normal>0 0 1</normal>
              <size>100 100</size>
            </plane>
          </geometry>
          <surface>
            <friction>
              <ode>
                <mu>100</mu>
                <mu2>50</mu2>
              </ode>
              <torsional>
                <ode/>
              </torsional>
            </friction>
            <contact>
              <ode/>
            </contact>
            <bounce/>
          </surface>
          <max_contacts>10</max_contacts>
        </collision>
        <visual name='visual'>
          <cast_shadows>0</cast_shadows>
          <geometry>
            <plane>
              <normal>0 0 1</normal>
              <size>100 100</size>
            </plane>
          </geometry>
          <material>
            <script>
              <uri>file://media/materials/scripts/gazebo.material</uri>
              <name>Gazebo/Grey</name>
            </script>
          </material>
        </visual>
        <self_collide>0</self_collide>
        <enable_wind>0</enable_wind>
        <kinematic>0</kinematic>
      </link>
    </model>
    <physics name='default_physics' default='0' type='ode'>
      <max_step_size>0.01</max_step_size>
      <real_time_factor>1</real_time_factor>
      <real_time_update_rate>100</real_time_update_rate>
    </physics>
    <gravity>0 0 -9.8</gravity>
    <magnetic_field>6e-06 2.3e-05 -4.2e-05</magnetic_field>
    <atmosphere type='adiabatic'/>
    <scene>
      <ambient>0.4 0.4 0.4 1</ambient>
      <background>0.7 0.7 0.7 1</background>
      <shadows>1</shadows>
    </scene>
    <wind/>
    <spherical_coordinates>
      <surface_model>EARTH_WGS84</surface_model>
      <latitude_deg>0</latitude_deg>
      <longitude_deg>0</longitude_deg>
      <elevation>0</elevation>
      <heading_deg>0</heading_deg>
    </spherical_coordinates>
    <model name='pioneer3at'>
      <link name='base_link'>
        <pose frame=''>0 0 0 0 -0 0</pose>
        <inertial>
          <pose frame=''>-0.095186 0 0.174739 0 -0 0</pose>
          <mass>22.6</mass>
          <inertia>
            <ixx>11.365</ixx>
            <ixy>-6.60484e-19</ixy>
            <ixz>0.0045133</ixz>
            <iyy>11.5163</iyy>
            <iyz>1.21249e-18</iyz>
            <izz>11.391</izz>
          </inertia>
        </inertial>
        <collision name='base_link_collision'>
          <pose frame=''>0 0 0.177 0 -0 0</pose>
          <geometry>
            <mesh>
              <scale>1 1 1</scale>
              <uri>/home/fmccastro/ROS_workspace/ws_1/src/amr-ros-config/description/meshes/p3at_meshes/chassis.stl</uri>
            </mesh>
          </geometry>
          <surface>
            <contact>
              <ode/>
            </contact>
            <friction>
              <ode/>
              <torsional>
                <ode/>
              </torsional>
            </friction>
            <bounce/>
          </surface>
          <max_contacts>10</max_contacts>
        </collision>
        <collision name='base_link_fixed_joint_lump__p3at_back_left_axle_collision_1'>
          <pose frame=''>-0.134 0.156 0.111 0 -0 0</pose>
          <geometry>
            <mesh>
              <scale>1 1 1</scale>
              <uri>/home/fmccastro/ROS_workspace/ws_1/src/amr-ros-config/description/meshes/p3at_meshes/axle.stl</uri>
            </mesh>
          </geometry>
          <surface>
            <contact>
              <ode/>
            </contact>
            <friction>
              <ode/>
              <torsional>
                <ode/>
              </torsional>
            </friction>
            <bounce/>
          </surface>
          <max_contacts>10</max_contacts>
        </collision>
        <collision name='base_link_fixed_joint_lump__p3at_back_left_hub_collision_2'>
          <pose frame=''>-0.134 0.197 0.111 0 -0 0</pose>
          <geometry>
            <mesh>
              <scale>1 1 1</scale>
              <uri>/home/fmccastro/ROS_workspace/ws_1/src/amr-ros-config/description/meshes/p3at_meshes/left_hubcap.stl</uri>
            </mesh>
          </geometry>
          <surface>
            <contact>
              <ode/>
            </contact>
            <friction>
              <ode/>
              <torsional>
                <ode/>
              </torsional>
            </friction>
            <bounce/>
          </surface>
          <max_contacts>10</max_contacts>
        </collision>
        <collision name='base_link_fixed_joint_lump__p3at_back_right_axle_collision_3'>
          <pose frame=''>-0.134 -0.156 0.111 0 -0 0</pose>
          <geometry>
            <mesh>
              <scale>1 1 1</scale>
              <uri>/home/fmccastro/ROS_workspace/ws_1/src/amr-ros-config/description/meshes/p3at_meshes/axle.stl</uri>
            </mesh>
          </geometry>
          <surface>
            <contact>
              <ode/>
            </contact>
            <friction>
              <ode/>
              <torsional>
                <ode/>
              </torsional>
            </friction>
            <bounce/>
          </surface>
          <max_contacts>10</max_contacts>
        </collision>
        <collision name='base_link_fixed_joint_lump__p3at_back_right_hub_collision_4'>
          <pose frame=''>-0.134 -0.197 0.111 0 -0 0</pose>
          <geometry>
            <mesh>
              <scale>1 1 1</scale>
              <uri>/home/fmccastro/ROS_workspace/ws_1/src/amr-ros-config/description/meshes/p3at_meshes/right_hubcap.stl</uri>
            </mesh>
          </geometry>
          <surface>
            <contact>
              <ode/>
            </contact>
            <friction>
              <ode/>
              <torsional>
                <ode/>
              </torsional>
            </friction>
            <bounce/>
          </surface>
          <max_contacts>10</max_contacts>
        </collision>
        <visual name='base_link_visual'>
          <pose frame=''>0 0 0.177 0 -0 0</pose>
          <geometry>
            <mesh>
              <scale>1 1 1</scale>
              <uri>/home/fmccastro/ROS_workspace/ws_1/src/amr-ros-config/description/meshes/p3at_meshes/chassis.stl</uri>
            </mesh>
          </geometry>
          <material>
            <script>
              <name>Gazebo/Red</name>
              <uri>file://media/materials/scripts/gazebo.material</uri>
            </script>
          </material>
        </visual>
        <visual name='base_link_fixed_joint_lump__back_sonar_visual_1'>
          <pose frame=''>-0.187 0 0.247 0 -0 0</pose>
          <geometry>
            <mesh>
              <scale>1 1 1</scale>
              <uri>/home/fmccastro/ROS_workspace/ws_1/src/amr-ros-config/description/meshes/p3at_meshes/back_sonar.stl</uri>
            </mesh>
          </geometry>
          <material>
            <script>
              <name>Gazebo/Yellow</name>
              <uri>file://media/materials/scripts/gazebo.material</uri>
            </script>
          </material>
        </visual>
        <visual name='base_link_fixed_joint_lump__front_sonar_visual_2'>
          <pose frame=''>0.193 0 0.25 0 -0 0</pose>
          <geometry>
            <mesh>
              <scale>1 1 1</scale>
              <uri>/home/fmccastro/ROS_workspace/ws_1/src/amr-ros-config/description/meshes/p3at_meshes/front_sonar.stl</uri>
            </mesh>
          </geometry>
          <material>
            <script>
              <name>Gazebo/Yellow</name>
              <uri>file://media/materials/scripts/gazebo.material</uri>
            </script>
          </material>
        </visual>
        <visual name='base_link_fixed_joint_lump__p3at_front_left_axle_visual_3'>
          <pose frame=''>0.135 0.156 0.111 0 -0 0</pose>
          <geometry>
            <mesh>
              <scale>1 1 1</scale>
              <uri>/home/fmccastro/ROS_workspace/ws_1/src/amr-ros-config/description/meshes/p3at_meshes/axle.stl</uri>
            </mesh>
          </geometry>
          <material>
            <script>
              <name>Gazebo/Grey</name>
              <uri>file://media/materials/scripts/gazebo.material</uri>
            </script>
          </material>
        </visual>
        <visual name='base_link_fixed_joint_lump__p3at_front_left_hub_visual_4'>
          <pose frame=''>0.135 0.197 0.111 0 -0 0</pose>
          <geometry>
            <mesh>
              <scale>1 1 1</scale>
              <uri>/home/fmccastro/ROS_workspace/ws_1/src/amr-ros-config/description/meshes/p3at_meshes/left_hubcap.stl</uri>
            </mesh>
          </geometry>
          <material>
            <script>
              <name>Gazebo/Yellow</name>
              <uri>file://media/materials/scripts/gazebo.material</uri>
            </script>
          </material>
        </visual>
        <visual name='base_link_fixed_joint_lump__p3at_front_right_axle_visual_5'>
          <pose frame=''>0.135 -0.156 0.111 0 -0 0</pose>
          <geometry>
            <mesh>
              <scale>1 1 1</scale>
              <uri>/home/fmccastro/ROS_workspace/ws_1/src/amr-ros-config/description/meshes/p3at_meshes/axle.stl</uri>
            </mesh>
          </geometry>
          <material>
            <script>
              <name>Gazebo/Grey</name>
              <uri>file://media/materials/scripts/gazebo.material</uri>
            </script>
          </material>
        </visual>
        <visual name='base_link_fixed_joint_lump__p3at_front_right_hub_visual_6'>
          <pose frame=''>0.135 -0.197 0.111 0 -0 0</pose>
          <geometry>
            <mesh>
              <scale>1 1 1</scale>
              <uri>/home/fmccastro/ROS_workspace/ws_1/src/amr-ros-config/description/meshes/p3at_meshes/right_hubcap.stl</uri>
            </mesh>
          </geometry>
          <material>
            <script>
              <name>Gazebo/Yellow</name>
              <uri>file://media/materials/scripts/gazebo.material</uri>
            </script>
          </material>
        </visual>
        <visual name='base_link_fixed_joint_lump__top_plate_visual_7'>
          <pose frame=''>0.003 0 0.274 0 -0 0</pose>
          <geometry>
            <mesh>
              <scale>1 1 1</scale>
              <uri>/home/fmccastro/ROS_workspace/ws_1/src/amr-ros-config/description/meshes/p3at_meshes/top.stl</uri>
            </mesh>
          </geometry>
          <material>
            <script>
              <name>Gazebo/Black</name>
              <uri>file://media/materials/scripts/gazebo.material</uri>
            </script>
          </material>
        </visual>
        <visual name='base_link_fixed_joint_lump__p3at_back_left_axle_visual_8'>
          <pose frame=''>-0.134 0.156 0.111 0 -0 0</pose>
          <geometry>
            <mesh>
              <scale>1 1 1</scale>
              <uri>/home/fmccastro/ROS_workspace/ws_1/src/amr-ros-config/description/meshes/p3at_meshes/axle.stl</uri>
            </mesh>
          </geometry>
          <material>
            <script>
              <name>Gazebo/Grey</name>
              <uri>file://media/materials/scripts/gazebo.material</uri>
            </script>
          </material>
        </visual>
        <visual name='base_link_fixed_joint_lump__p3at_back_left_hub_visual_9'>
          <pose frame=''>-0.134 0.197 0.111 0 -0 0</pose>
          <geometry>
            <mesh>
              <scale>1 1 1</scale>
              <uri>/home/fmccastro/ROS_workspace/ws_1/src/amr-ros-config/description/meshes/p3at_meshes/left_hubcap.stl</uri>
            </mesh>
          </geometry>
          <material>
            <script>
              <name>Gazebo/Yellow</name>
              <uri>file://media/materials/scripts/gazebo.material</uri>
            </script>
          </material>
        </visual>
        <visual name='base_link_fixed_joint_lump__p3at_back_right_axle_visual_10'>
          <pose frame=''>-0.134 -0.156 0.111 0 -0 0</pose>
          <geometry>
            <mesh>
              <scale>1 1 1</scale>
              <uri>/home/fmccastro/ROS_workspace/ws_1/src/amr-ros-config/description/meshes/p3at_meshes/axle.stl</uri>
            </mesh>
          </geometry>
          <material>
            <script>
              <name>Gazebo/Grey</name>
              <uri>file://media/materials/scripts/gazebo.material</uri>
            </script>
          </material>
        </visual>
        <visual name='base_link_fixed_joint_lump__p3at_back_right_hub_visual_11'>
          <pose frame=''>-0.134 -0.197 0.111 0 -0 0</pose>
          <geometry>
            <mesh>
              <scale>1 1 1</scale>
              <uri>/home/fmccastro/ROS_workspace/ws_1/src/amr-ros-config/description/meshes/p3at_meshes/right_hubcap.stl</uri>
            </mesh>
          </geometry>
          <material>
            <script>
              <name>Gazebo/Yellow</name>
              <uri>file://media/materials/scripts/gazebo.material</uri>
            </script>
          </material>
        </visual>
        <velocity_decay/>
        <velocity_decay/>
        <velocity_decay/>
        <velocity_decay/>
        <velocity_decay/>
        <velocity_decay/>
        <velocity_decay/>
        <velocity_decay/>
        <velocity_decay/>
        <velocity_decay/>
        <velocity_decay/>
        <gravity>1</gravity>
        <velocity_decay/>
        <self_collide>0</self_collide>
        <enable_wind>0</enable_wind>
        <kinematic>0</kinematic>
      </link>
      <link name='p3at_front_left_wheel'>
        <pose frame=''>0.135 0.197 0.111 0 -0 0</pose>
        <inertial>
          <pose frame=''>0 0 0 0 -0 0</pose>
          <mass>1.2</mass>
          <inertia>
            <ixx>0.0124118</ixx>
            <ixy>0</ixy>
            <ixz>0</ixz>
            <iyy>0.0152182</iyy>
            <iyz>0</iyz>
            <izz>0.011764</izz>
          </inertia>
        </inertial>
        <collision name='p3at_front_left_wheel_collision'>
          <pose frame=''>0 0 0 -1.5708 0 0</pose>
          <geometry>
            <cylinder>
              <length>0.075</length>
              <radius>0.111</radius>
            </cylinder>
          </geometry>
          <surface>
            <contact>
              <ode>
                <kp>1e+06</kp>
                <kd>100</kd>
                <max_vel>1</max_vel>
                <min_depth>0</min_depth>
              </ode>
            </contact>
            <friction>
              <ode>
                <mu>1</mu>
                <mu2>1</mu2>
              </ode>
              <torsional>
                <ode/>
              </torsional>
            </friction>
            <bounce/>
          </surface>
          <max_contacts>10</max_contacts>
        </collision>
        <visual name='p3at_front_left_wheel_visual'>
          <pose frame=''>0 0 0 0 -0 0</pose>
          <geometry>
            <mesh>
              <scale>1 1 1</scale>
              <uri>/home/fmccastro/ROS_workspace/ws_1/src/amr-ros-config/description/meshes/p3at_meshes/wheel.stl</uri>
            </mesh>
          </geometry>
          <material>
            <script>
              <name>Gazebo/Black</name>
              <uri>file://media/materials/scripts/gazebo.material</uri>
            </script>
          </material>
        </visual>
        <velocity_decay/>
        <gravity>1</gravity>
        <velocity_decay/>
        <self_collide>0</self_collide>
        <enable_wind>0</enable_wind>
        <kinematic>0</kinematic>
      </link>
      <joint name='p3at_front_left_wheel_joint' type='revolute'>
        <child>p3at_front_left_wheel</child>
        <parent>base_link</parent>
        <axis>
          <xyz>0 1 0</xyz>
          <limit>
            <lower>-1e+16</lower>
            <upper>1e+16</upper>
          </limit>
          <dynamics>
            <spring_reference>0</spring_reference>
            <spring_stiffness>0</spring_stiffness>
          </dynamics>
          <use_parent_model_frame>0</use_parent_model_frame>
        </axis>
      </joint>
      <link name='p3at_front_right_wheel'>
        <pose frame=''>0.135 -0.197 0.111 0 -0 0</pose>
        <inertial>
          <pose frame=''>0 0 0 0 -0 0</pose>
          <mass>1.2</mass>
          <inertia>
            <ixx>0.0124118</ixx>
            <ixy>0</ixy>
            <ixz>0</ixz>
            <iyy>0.0152182</iyy>
            <iyz>0</iyz>
            <izz>0.011764</izz>
          </inertia>
        </inertial>
        <collision name='p3at_front_right_wheel_collision'>
          <pose frame=''>0 0 0 -1.5708 0 0</pose>
          <geometry>
            <cylinder>
              <length>0.075</length>
              <radius>0.111</radius>
            </cylinder>
          </geometry>
          <surface>
            <contact>
              <ode>
                <kp>1e+06</kp>
                <kd>100</kd>
                <max_vel>1</max_vel>
                <min_depth>0</min_depth>
              </ode>
            </contact>
            <friction>
              <ode>
                <mu>1</mu>
                <mu2>1</mu2>
              </ode>
              <torsional>
                <ode/>
              </torsional>
            </friction>
            <bounce/>
          </surface>
          <max_contacts>10</max_contacts>
        </collision>
        <visual name='p3at_front_right_wheel_visual'>
          <pose frame=''>0 0 0 0 -0 0</pose>
          <geometry>
            <mesh>
              <scale>1 1 1</scale>
              <uri>/home/fmccastro/ROS_workspace/ws_1/src/amr-ros-config/description/meshes/p3at_meshes/wheel.stl</uri>
            </mesh>
          </geometry>
          <material>
            <script>
              <name>Gazebo/Black</name>
              <uri>file://media/materials/scripts/gazebo.material</uri>
            </script>
          </material>
        </visual>
        <velocity_decay/>
        <gravity>1</gravity>
        <velocity_decay/>
        <self_collide>0</self_collide>
        <enable_wind>0</enable_wind>
        <kinematic>0</kinematic>
      </link>
      <joint name='p3at_front_right_wheel_joint' type='revolute'>
        <child>p3at_front_right_wheel</child>
        <parent>base_link</parent>
        <axis>
          <xyz>0 1 0</xyz>
          <limit>
            <lower>-1e+16</lower>
            <upper>1e+16</upper>
          </limit>
          <dynamics>
            <spring_reference>0</spring_reference>
            <spring_stiffness>0</spring_stiffness>
          </dynamics>
          <use_parent_model_frame>0</use_parent_model_frame>
        </axis>
      </joint>
      <link name='p3at_back_left_wheel'>
        <pose frame=''>-0.134 0.197 0.111 0 -0 0</pose>
        <inertial>
          <pose frame=''>0 0 0 0 -0 0</pose>
          <mass>1.2</mass>
          <inertia>
            <ixx>0.0124118</ixx>
            <ixy>0</ixy>
            <ixz>0</ixz>
            <iyy>0.0152182</iyy>
            <iyz>0</iyz>
            <izz>0.011764</izz>
          </inertia>
        </inertial>
        <collision name='p3at_back_left_wheel_collision'>
          <pose frame=''>0 0 0 -1.5708 0 0</pose>
          <geometry>
            <cylinder>
              <length>0.075</length>
              <radius>0.111</radius>
            </cylinder>
          </geometry>
          <surface>
            <contact>
              <ode>
                <kp>1e+06</kp>
                <kd>100</kd>
                <max_vel>1</max_vel>
                <min_depth>0</min_depth>
              </ode>
            </contact>
            <friction>
              <ode>
                <mu>1</mu>
                <mu2>1</mu2>
              </ode>
              <torsional>
                <ode/>
              </torsional>
            </friction>
            <bounce/>
          </surface>
          <max_contacts>10</max_contacts>
        </collision>
        <visual name='p3at_back_left_wheel_visual'>
          <pose frame=''>0 0 0 0 -0 0</pose>
          <geometry>
            <mesh>
              <scale>1 1 1</scale>
              <uri>/home/fmccastro/ROS_workspace/ws_1/src/amr-ros-config/description/meshes/p3at_meshes/wheel.stl</uri>
            </mesh>
          </geometry>
          <material>
            <script>
              <name>Gazebo/Black</name>
              <uri>file://media/materials/scripts/gazebo.material</uri>
            </script>
          </material>
        </visual>
        <velocity_decay/>
        <gravity>1</gravity>
        <velocity_decay/>
        <self_collide>0</self_collide>
        <enable_wind>0</enable_wind>
        <kinematic>0</kinematic>
      </link>
      <joint name='p3at_back_left_wheel_joint' type='revolute'>
        <child>p3at_back_left_wheel</child>
        <parent>base_link</parent>
        <axis>
          <xyz>0 1 0</xyz>
          <limit>
            <lower>-1e+16</lower>
            <upper>1e+16</upper>
          </limit>
          <dynamics>
            <spring_reference>0</spring_reference>
            <spring_stiffness>0</spring_stiffness>
          </dynamics>
          <use_parent_model_frame>0</use_parent_model_frame>
        </axis>
      </joint>
      <link name='p3at_back_right_wheel'>
        <pose frame=''>-0.134 -0.197 0.111 0 -0 0</pose>
        <inertial>
          <pose frame=''>0 0 0 0 -0 0</pose>
          <mass>1.2</mass>
          <inertia>
            <ixx>0.0124118</ixx>
            <ixy>0</ixy>
            <ixz>0</ixz>
            <iyy>0.0152182</iyy>
            <iyz>0</iyz>
            <izz>0.011764</izz>
          </inertia>
        </inertial>
        <collision name='p3at_back_right_wheel_collision'>
          <pose frame=''>0 0 0 -1.5708 0 0</pose>
          <geometry>
            <cylinder>
              <length>0.075</length>
              <radius>0.111</radius>
            </cylinder>
          </geometry>
          <surface>
            <contact>
              <ode>
                <kp>1e+06</kp>
                <kd>100</kd>
                <max_vel>1</max_vel>
                <min_depth>0</min_depth>
              </ode>
            </contact>
            <friction>
              <ode>
                <mu>1</mu>
                <mu2>1</mu2>
              </ode>
              <torsional>
                <ode/>
              </torsional>
            </friction>
            <bounce/>
          </surface>
          <max_contacts>10</max_contacts>
        </collision>
        <visual name='p3at_back_right_wheel_visual'>
          <pose frame=''>0 0 0 0 -0 0</pose>
          <geometry>
            <mesh>
              <scale>1 1 1</scale>
              <uri>/home/fmccastro/ROS_workspace/ws_1/src/amr-ros-config/description/meshes/p3at_meshes/wheel.stl</uri>
            </mesh>
          </geometry>
          <material>
            <script>
              <name>Gazebo/Black</name>
              <uri>file://media/materials/scripts/gazebo.material</uri>
            </script>
          </material>
        </visual>
        <velocity_decay/>
        <gravity>1</gravity>
        <velocity_decay/>
        <self_collide>0</self_collide>
        <enable_wind>0</enable_wind>
        <kinematic>0</kinematic>
      </link>
      <joint name='p3at_back_right_wheel_joint' type='revolute'>
        <child>p3at_back_right_wheel</child>
        <parent>base_link</parent>
        <axis>
          <xyz>0 1 0</xyz>
          <limit>
            <lower>-1e+16</lower>
            <upper>1e+16</upper>
          </limit>
          <dynamics>
            <spring_reference>0</spring_reference>
            <spring_stiffness>0</spring_stiffness>
          </dynamics>
          <use_parent_model_frame>0</use_parent_model_frame>
        </axis>
      </joint>
      <static>0</static>
      <plugin name='skid_steer_drive_controller' filename='libgazebo_ros_skid_steer_drive.so'>
        <updateRate>100.0</updateRate>
        <robotNamespace>pioneer3at</robotNamespace>
        <leftFrontJoint>p3at_front_left_wheel_joint</leftFrontJoint>
        <rightFrontJoint>p3at_front_right_wheel_joint</rightFrontJoint>
        <leftRearJoint>p3at_back_left_wheel_joint</leftRearJoint>
        <rightRearJoint>p3at_back_right_wheel_joint</rightRearJoint>
        <wheelSeparation>0.4</wheelSeparation>
        <wheelDiameter>0.222</wheelDiameter>
        <robotBaseFrame>base_link</robotBaseFrame>
        <MaxForce>5.0</MaxForce>
        <torque>200</torque>
        <commandTopic>cmd_vel</commandTopic>
        <odometryTopic>odom</odometryTopic>
        <odometryFrame>odom</odometryFrame>
        <broadcastTF>1</broadcastTF>
        <covariance_x>0.0001</covariance_x>
        <covariance_y>0.0001</covariance_y>
        <covariance_yaw>0.01</covariance_yaw>
        <publishWheelJointState>1</publishWheelJointState>
      </plugin>
      <pose frame=''>0 0 1 0 -0 0</pose>
    </model>
    <state world_name='default'>
      <sim_time>86 650000000</sim_time>
      <real_time>87 104428220</real_time>
      <wall_time>1587522944 752140090</wall_time>
      <iterations>8665</iterations>
      <model name='ground_plane'>
        <pose frame=''>0 0 0 0 -0 0</pose>
        <scale>1 1 1</scale>
        <link name='link'>
          <pose frame=''>0 0 0 0 -0 0</pose>
          <velocity>0 0 0 0 -0 0</velocity>
          <acceleration>0 0 0 0 -0 0</acceleration>
          <wrench>0 0 0 0 -0 0</wrench>
        </link>
      </model>
      <model name='pioneer3at'>
        <pose frame=''>-0.011326 -0.017225 -1e-05 0.0001 -0.000719 -0.013381</pose>
        <scale>1 1 1</scale>
        <link name='base_link'>
          <pose frame=''>-0.011326 -0.017225 -1e-05 0.0001 -0.000719 -0.013381</pose>
          <velocity>-0.000159 1.6e-05 4e-05 -3.6e-05 4e-06 -1e-06</velocity>
          <acceleration>-0 0 -0 0 -0 0</acceleration>
          <wrench>-0 0 -0 0 -0 0</wrench>
        </link>
        <link name='p3at_back_left_wheel'>
          <pose frame=''>-0.14275 0.181515 0.110967 0.000473 -0.09735 -0.013435</pose>
          <velocity>-0.000158 1.6e-05 4.4e-05 -0.000144 -0.001423 -1e-06</velocity>
          <acceleration>-0 0 0 -0 -0 -0</acceleration>
          <wrench>-0 0 0 0 -0 0</wrench>
        </link>
        <link name='p3at_back_right_wheel'>
          <pose frame=''>-0.148022 -0.212449 0.11096 0.000602 -0.101443 -0.013451</pose>
          <velocity>-0.000158 1.7e-05 5.4e-05 -0.000155 -0.001425 -1e-06</velocity>
          <acceleration>-0 0 -0 -0 -0 -0</acceleration>
          <wrench>-0 0 -0 0 -0 0</wrench>
        </link>
        <link name='p3at_front_left_wheel'>
          <pose frame=''>0.126227 0.177947 0.110967 0.000679 -0.059966 -0.013429</pose>
          <velocity>-0.000158 1.3e-05 2.5e-05 -0.000113 -0.001423 -2e-06</velocity>
          <acceleration>-0 0 -0 -0 -0 -0</acceleration>
          <wrench>-0 0 -0 0 -0 0</wrench>
        </link>
        <link name='p3at_front_right_wheel'>
          <pose frame=''>0.120946 -0.216025 0.111077 0.000103 0.012161 -0.013379</pose>
          <velocity>-0.000158 2e-05 4.7e-05 -3.6e-05 -6e-05 -0</velocity>
          <acceleration>-0 0 -0 0 -0 0</acceleration>
          <wrench>-0 0 -0 0 -0 0</wrench>
        </link>
      </model>
      <light name='sun'>
        <pose frame=''>0 0 10 0 -0 0</pose>
      </light>
    </state>
    <gui fullscreen='0'>
      <camera name='user_camera'>
        <pose frame=''>5 -5 2 0 0.275643 2.35619</pose>
        <view_controller>orbit</view_controller>
        <projection_type>perspective</projection_type>
      </camera>
    </gui>
  </world>
</sdf>
